WARNING: Retrying (Retry(total=4, connect=None, read=None, redirect=None, status=None)) after connection broken by 'ReadTimeoutError("HTTPSConnectionPool(host='pypi.org', port=443): Read timed out. (read timeout=15)")': /simple/pip/
WARNING: Retrying (Retry(total=3, connect=None, read=None, redirect=None, status=None)) after connection broken by 'ReadTimeoutError("HTTPSConnectionPool(host='pypi.org', port=443): Read timed out. (read timeout=15)")': /simple/pip/
WARNING: Retrying (Retry(total=2, connect=None, read=None, redirect=None, status=None)) after connection broken by 'ReadTimeoutError("HTTPSConnectionPool(host='pypi.org', port=443): Read timed out. (read timeout=15)")': /simple/pip/
WARNING: Retrying (Retry(total=1, connect=None, read=None, redirect=None, status=None)) after connection broken by 'ReadTimeoutError("HTTPSConnectionPool(host='pypi.org', port=443): Read timed out. (read timeout=15)")': /simple/pip/
WARNING: Retrying (Retry(total=0, connect=None, read=None, redirect=None, status=None)) after connection broken by 'ReadTimeoutError("HTTPSConnectionPool(host='pypi.org', port=443): Read timed out. (read timeout=15)")': /simple/pip/
WARNING: Retrying (Retry(total=4, connect=None, read=None, redirect=None, status=None)) after connection broken by 'ReadTimeoutError("HTTPSConnectionPool(host='developer.download.nvidia.com', port=443): Read timed out. (read timeout=15)")': /compute/redist/pip/
WARNING: Retrying (Retry(total=3, connect=None, read=None, redirect=None, status=None)) after connection broken by 'ReadTimeoutError("HTTPSConnectionPool(host='developer.download.nvidia.com', port=443): Read timed out. (read timeout=15)")': /compute/redist/pip/
WARNING: Retrying (Retry(total=2, connect=None, read=None, redirect=None, status=None)) after connection broken by 'ReadTimeoutError("HTTPSConnectionPool(host='developer.download.nvidia.com', port=443): Read timed out. (read timeout=15)")': /compute/redist/pip/
WARNING: Retrying (Retry(total=1, connect=None, read=None, redirect=None, status=None)) after connection broken by 'ReadTimeoutError("HTTPSConnectionPool(host='developer.download.nvidia.com', port=443): Read timed out. (read timeout=15)")': /compute/redist/pip/
WARNING: Retrying (Retry(total=0, connect=None, read=None, redirect=None, status=None)) after connection broken by 'ReadTimeoutError("HTTPSConnectionPool(host='developer.download.nvidia.com', port=443): Read timed out. (read timeout=15)")': /compute/redist/pip/
/var/spool/PBS/mom_priv/jobs/287817.hpc1.hpc.SC: /datahome/scratch-small-local/287817-hpc1-hpc/myenv/bin/pip: /scratch-small-local/287808-hpc1-hpc/myenv/bin/python3: bad interpreter: No such file or directory
mkdir: cannot create directory ‘wav2vec2-xls-r-300m-asr_af’: File exists
Resolving data files:   0%|          | 0/50 [00:00<?, ?it/s]Resolving data files:   4%|▍         | 2/50 [00:00<00:11,  4.15it/s]Resolving data files:   4%|▍         | 2/50 [15:31<6:12:47, 465.98s/it]
Traceback (most recent call last):
  File "train.py", line 283, in <module>
    main()
  File "train.py", line 275, in main
    model.load_datasets()
  File "train.py", line 83, in load_datasets
    dataset = load_dataset(f"lucas-meyer/{self.dataset_name}") # 31 Minutes !!!
  File "/datahome/scratch-small-local/287817-hpc1-hpc/myenv/lib/python3.8/site-packages/datasets/load.py", line 2129, in load_dataset
    builder_instance = load_dataset_builder(
  File "/datahome/scratch-small-local/287817-hpc1-hpc/myenv/lib/python3.8/site-packages/datasets/load.py", line 1815, in load_dataset_builder
    dataset_module = dataset_module_factory(
  File "/datahome/scratch-small-local/287817-hpc1-hpc/myenv/lib/python3.8/site-packages/datasets/load.py", line 1512, in dataset_module_factory
    raise e1 from None
  File "/datahome/scratch-small-local/287817-hpc1-hpc/myenv/lib/python3.8/site-packages/datasets/load.py", line 1489, in dataset_module_factory
    return HubDatasetModuleFactoryWithoutScript(
  File "/datahome/scratch-small-local/287817-hpc1-hpc/myenv/lib/python3.8/site-packages/datasets/load.py", line 1048, in get_module
    data_files = DataFilesDict.from_patterns(
  File "/datahome/scratch-small-local/287817-hpc1-hpc/myenv/lib/python3.8/site-packages/datasets/data_files.py", line 674, in from_patterns
    DataFilesList.from_patterns(
  File "/datahome/scratch-small-local/287817-hpc1-hpc/myenv/lib/python3.8/site-packages/datasets/data_files.py", line 589, in from_patterns
    origin_metadata = _get_origin_metadata(data_files, download_config=download_config)
  File "/datahome/scratch-small-local/287817-hpc1-hpc/myenv/lib/python3.8/site-packages/datasets/data_files.py", line 504, in _get_origin_metadata
    return thread_map(
  File "/datahome/scratch-small-local/287817-hpc1-hpc/myenv/lib/python3.8/site-packages/tqdm/contrib/concurrent.py", line 69, in thread_map
    return _executor_map(ThreadPoolExecutor, fn, *iterables, **tqdm_kwargs)
  File "/datahome/scratch-small-local/287817-hpc1-hpc/myenv/lib/python3.8/site-packages/tqdm/contrib/concurrent.py", line 51, in _executor_map
    return list(tqdm_class(ex.map(fn, *iterables, chunksize=chunksize), **kwargs))
  File "/datahome/scratch-small-local/287817-hpc1-hpc/myenv/lib/python3.8/site-packages/tqdm/std.py", line 1182, in __iter__
    for obj in iterable:
  File "/home/apps2/python/3.8.5/lib/python3.8/concurrent/futures/_base.py", line 611, in result_iterator
    yield fs.pop().result()
  File "/home/apps2/python/3.8.5/lib/python3.8/concurrent/futures/_base.py", line 439, in result
    return self.__get_result()
  File "/home/apps2/python/3.8.5/lib/python3.8/concurrent/futures/_base.py", line 388, in __get_result
    raise self._exception
  File "/home/apps2/python/3.8.5/lib/python3.8/concurrent/futures/thread.py", line 57, in run
    result = self.fn(*self.args, **self.kwargs)
  File "/datahome/scratch-small-local/287817-hpc1-hpc/myenv/lib/python3.8/site-packages/datasets/data_files.py", line 484, in _get_single_origin_metadata
    resolved_path = fs.resolve_path(data_file)
  File "/datahome/scratch-small-local/287817-hpc1-hpc/myenv/lib/python3.8/site-packages/huggingface_hub/hf_file_system.py", line 147, in resolve_path
    repo_and_revision_exist, err = self._repo_and_revision_exist(repo_type, repo_id, revision)
  File "/datahome/scratch-small-local/287817-hpc1-hpc/myenv/lib/python3.8/site-packages/huggingface_hub/hf_file_system.py", line 100, in _repo_and_revision_exist
    self._api.repo_info(repo_id, revision=revision, repo_type=repo_type)
  File "/datahome/scratch-small-local/287817-hpc1-hpc/myenv/lib/python3.8/site-packages/huggingface_hub/utils/_validators.py", line 118, in _inner_fn
    return fn(*args, **kwargs)
  File "/datahome/scratch-small-local/287817-hpc1-hpc/myenv/lib/python3.8/site-packages/huggingface_hub/hf_api.py", line 1868, in repo_info
    return method(
  File "/datahome/scratch-small-local/287817-hpc1-hpc/myenv/lib/python3.8/site-packages/huggingface_hub/utils/_validators.py", line 118, in _inner_fn
    return fn(*args, **kwargs)
  File "/datahome/scratch-small-local/287817-hpc1-hpc/myenv/lib/python3.8/site-packages/huggingface_hub/hf_api.py", line 1740, in dataset_info
    r = get_session().get(path, headers=headers, timeout=timeout, params=params)
  File "/datahome/scratch-small-local/287817-hpc1-hpc/myenv/lib/python3.8/site-packages/requests/sessions.py", line 602, in get
    return self.request("GET", url, **kwargs)
  File "/datahome/scratch-small-local/287817-hpc1-hpc/myenv/lib/python3.8/site-packages/requests/sessions.py", line 589, in request
    resp = self.send(prep, **send_kwargs)
  File "/datahome/scratch-small-local/287817-hpc1-hpc/myenv/lib/python3.8/site-packages/requests/sessions.py", line 703, in send
    r = adapter.send(request, **kwargs)
  File "/datahome/scratch-small-local/287817-hpc1-hpc/myenv/lib/python3.8/site-packages/huggingface_hub/utils/_http.py", line 63, in send
    return super().send(request, *args, **kwargs)
  File "/datahome/scratch-small-local/287817-hpc1-hpc/myenv/lib/python3.8/site-packages/requests/adapters.py", line 501, in send
    raise ConnectionError(err, request=request)
requests.exceptions.ConnectionError: (ProtocolError('Connection aborted.', TimeoutError(110, 'Connection timed out')), '(Request ID: 8000b769-cba3-4fe4-8dd6-411c91fd909c)')
